<?xml version="1.0" ?>
<robot name="robot">
    <!-- Links -->
    <link name="world" />
    <!-- Arm Links -->
    <link name="shoulder">
        <visual>
            <geometry>
                <mesh filename="package://basic_velocity_control/description/models/shoulder.stl" />
            </geometry>
            <material name="aluminum">
                <color rgba="1 1 1 1" />
            </material>
        </visual>
        <collision>
            <geometry>
                <mesh filename="package://basic_velocity_control/description/models/shoulder.stl" />
            </geometry>
        </collision>
        <inertial>
            <origin rpy="0 0 0" xyz="0 -0.500 0" />
            <mass value="445.83607510" />
            <inertia ixx="43.01142466" ixy="0.00000007" ixz="0.00000003" iyy="11.71683688" iyz="-0.00000154" izz="43.01142473" />
        </inertial>
    </link>
    <link name="upperarm">
        <visual>
            <geometry>
                <mesh filename="package://basic_velocity_control/description/models/upperarm.stl" />
            </geometry>
            <material name="aluminum">
                <color rgba="1 1 1 1" />
            </material>
        </visual>
        <collision>
            <geometry>
                <mesh filename="package://basic_velocity_control/description/models/upperarm.stl" />
            </geometry>
        </collision>
        <inertial>
            <origin rpy="0 0 0" xyz="1.34345613 0 0" />
            <mass value="1897.69177373" />
            <inertia ixx="66.99460092" ixy="0.00000001" ixz="0.00000001" iyy="2234.31516869" iyz="-0.00000152" izz="2258.25308259" />
        </inertial>
    </link>
    <link name="forearm">
        <visual>
            <geometry>
                <mesh filename="package://basic_velocity_control/description/models/forearm.stl" />
            </geometry>
            <material name="aluminum">
                <color rgba="1 1 1 1" />
            </material>
        </visual>
        <collision>
            <geometry>
                <mesh filename="package://basic_velocity_control/description/models/forearm.stl" />
            </geometry>
        </collision>
        <inertial>
            <origin rpy="0 0 0" xyz="1.41553743 0 0" />
            <mass value="722.16061394" />
            <inertia ixx="9.87773403" ixy="0.00000001" ixz="0.00000001" iyy="801.33982537" iyz="0.00000001" izz="804.66073917" />
        </inertial>
    </link>
    <link name="tool">
        <visual>
            <geometry>
                <sphere radius="0.05" />
            </geometry>
            <material name="aluminum">
                <color rgba="1 1 1 1" />
            </material>
        </visual>
        <collision>
            <geometry>
                <sphere radius="0.1" />
            </geometry>
        </collision>
        <inertial>
            <origin rpy="0 0 0" xyz="0 0 0" />
            <mass value="1.0" />
            <inertia ixx="0.1" ixy="0.1" ixz="0.1" iyy="0.1" iyz="0.1" izz="0.1" />
        </inertial>
    </link>
    <link name="dummy" />
    <!-- Gripper links -->
    <link name="gripper_bottom">
        <visual>
            <geometry>
                <mesh filename="package://basic_velocity_control/description/models/gripper-bottom.stl" />
            </geometry>
            <material name="aluminum">
                <color rgba="1 1 1 1" />
            </material>
        </visual>
        <collision>
            <geometry>
                <mesh filename="package://basic_velocity_control/description/models/gripper-bottom.stl" />
            </geometry>
        </collision>
        <inertial>
            <origin rpy="0 0 0" xyz="0 0 0" />
            <mass value="1.0" />
            <inertia ixx="0.1" ixy="0.1" ixz="0.1" iyy="0.1" iyz="0.1" izz="0.1" />
        </inertial>
    </link>
    <link name="gripper_top">
        <visual>
            <geometry>
                <mesh filename="package://basic_velocity_control/description/models/gripper-top.stl" />
            </geometry>
            <material name="aluminum">
                <color rgba="1 1 1 1" />
            </material>
        </visual>
        <collision>
            <geometry>
                <mesh filename="package://basic_velocity_control/description/models/gripper-top.stl" />
            </geometry>
        </collision>
        <inertial>
            <origin rpy="0 0 0" xyz="0 0 0" />
            <mass value="1.0" />
            <inertia ixx="0.1" ixy="0.1" ixz="0.1" iyy="0.1" iyz="0.1" izz="0.1" />
        </inertial>
    </link>
    <!-- Arm joints -->
    <joint name="shoulder_joint" type="revolute">
        <origin rpy="1.5708 0 0" xyz="0 0 1" />
        <axis xyz="0 1 0" />
        <parent link="world" />
        <child link="shoulder" />
        <limit effort="100000" velocity="1.0" lower="-1.5708" upper="1.5708" />
        <dynamics damping="0.7" friction="1.4" />
    </joint>
    <joint name="upperarm_joint" type="revolute">
        <origin rpy="0 0 0" xyz="0 0 0" />
        <axis xyz="0 0 1" />
        <parent link="shoulder" />
        <child link="upperarm" />
        <limit effort="100000" velocity="1.0" lower="-0.8417" upper="1.5708" />
        <dynamics damping="0.7" friction="1.4" />
    </joint>
    <joint name="forearm_joint" type="revolute">
        <origin rpy="0 0 0" xyz="3.5 0 0" />
        <axis xyz="0 0 1" />
        <parent link="upperarm" />
        <child link="forearm" />
        <limit effort="100000" velocity="1.0" lower="-1.5708" upper="0" />
        <dynamics damping="0.7" friction="1.4" />
    </joint>
    <joint name="wrist" type="fixed">
        <origin rpy="0 0 0" xyz="3.5 0.0 0.0" />
        <parent link="forearm" />
        <child link="tool" />
    </joint>
    <!-- Gripper Joints -->
    <joint name="gripper" type="prismatic">
        <origin rpy="1.5708 0 0" xyz="0.15 0.0 0.0" />
        <parent link="tool" />
        <mimic joint="gripper_top_mimic" multiplier="-1.0" offset="0.0" />
        <mimic joint="gripper_bottom_mimic" multiplier="1.0" offset="0.0" />
        <limit effort="100000" velocity="1.0" lower="0" upper="0.0688" />
        <child link="dummy" />
        <dynamics damping="0.7" friction="1.4" />
    </joint>
    <!-- Mimics -->
    <joint name="gripper_bottom_mimic" type="prismatic">
        <origin rpy="1.5708 0 0" xyz="0.15 0.0 0.0" />
        <axis xyz="0 0 1" />
        <parent link="tool" />
        <child link="gripper_bottom" />
        <limit effort="100000" velocity="1.0" lower="0" upper="0.0688" />
        <dynamics damping="0.7" friction="1.4" />
    </joint>
    <joint name="gripper_top_mimic" type="prismatic">
        <origin rpy="1.5708 0 0" xyz="0.15 0.0 0.0" />
        <axis xyz="0 0 1" />
        <parent link="tool" />
        <child link="gripper_top" />
        <limit effort="100000" velocity="1.0" lower="-0.0688" upper="0" />
        <dynamics damping="0.7" friction="1.4" />
    </joint>
    <!-- Transmissions -->
    <transmission name="trans_shoulder">
        <type>transmission_interface/SimpleTransmission</type>
        <joint name="shoulder_joint">
            <hardwareInterface>hardware_interface/VelocityJointInterface</hardwareInterface>
        </joint>
        <actuator name="shoulder_motor">
            <mechanicalReduction>1</mechanicalReduction>
            <hardwareInterface>hardware_interface/VelocityJointInterface</hardwareInterface>
        </actuator>
    </transmission>
    <transmission name="trans_upperarm">
        <type>transmission_interface/SimpleTransmission</type>
        <joint name="upperarm_joint">
            <hardwareInterface>hardware_interface/VelocityJointInterface</hardwareInterface>
        </joint>
        <actuator name="upperarm_motor">
            <mechanicalReduction>1</mechanicalReduction>
            <hardwareInterface>hardware_interface/VelocityJointInterface</hardwareInterface>
        </actuator>
    </transmission>
    <transmission name="trans_forearm">
        <type>transmission_interface/SimpleTransmission</type>
        <joint name="forearm_joint">
            <hardwareInterface>hardware_interface/VelocityJointInterface</hardwareInterface>
        </joint>
        <actuator name="forearm_motor">
            <mechanicalReduction>1</mechanicalReduction>
            <hardwareInterface>hardware_interface/VelocityJointInterface</hardwareInterface>
        </actuator>
    </transmission>
    <transmission name="trans_gripper">
        <type>transmission_interface/SimpleTransmission</type>
        <joint name="gripper">
            <hardwareInterface>hardware_interface/PositionJointInterface</hardwareInterface>
        </joint>
        <actuator name="gripper_motor">
            <hardwareInterface>hardware_interface/PositionJointInterface</hardwareInterface>
            <mechanicalReduction>1</mechanicalReduction>
        </actuator>
    </transmission>
    <!-- Plugins -->
    <gazebo>
        <plugin name="gazebo_ros_control" filename="libgazebo_ros_control.so">
            <robotNamespace>/</robotNamespace>
        </plugin>
    </gazebo>
    <transmission name="trans_gripper_bottom_mimic">
        <type>transmission_interface/SimpleTransmission</type>
        <joint name="gripper_bottom_mimic">
            <hardwareInterface>hardware_interface/EffortJointInterface</hardwareInterface>
        </joint>
        <actuator name="gripper_bottom_mimic_motor">
            <hardwareInterface>hardware_interface/EffortJointInterface</hardwareInterface>
            <mechanicalReduction>1</mechanicalReduction>
        </actuator>
    </transmission>
    <transmission name="trans_gripper_top_mimic">
        <type>transmission_interface/SimpleTransmission</type>
        <joint name="gripper_top_mimic">
            <hardwareInterface>hardware_interface/EffortJointInterface</hardwareInterface>
        </joint>
        <actuator name="gripper_top_mimic_motor">
            <hardwareInterface>hardware_interface/EffortJointInterface</hardwareInterface>
            <mechanicalReduction>1</mechanicalReduction>
        </actuator>
    </transmission>
</robot>

